<?xml version="1.0"?>
<robot xmlns:xacro="http://www.ros.org/wiki/xacro">

<!--<xacro:include filename="$(find track_robot_description)/urdf/common.urdf.xacro" />-->
<!--<xacro:include filename="$(find track_robot_description)/urdf/materials.urdf.xacro" />-->

<xacro:macro name="wheel" params="name parent *origin">

<joint name="${name}_joint" type="continuous" >
<parent link="${parent}" />
<child link="${name}" />
<xacro:insert_block name="origin" />
<axis xyz="0 0 1" rpy="0 0 0" />
<limit effort="30" velocity="0.2" />
</joint>

<link name="${name}">
<visual>
<!-- <origin xyz="0 0 -${M_PI/2}" rpy="0 ${M_PI/2} 0" /> -->
<geometry>
<cylinder radius="0.1" length="0.1" />
</geometry>
<material name="LightGrey2"/>
</visual>
<collision >
<!-- <origin xyz="0 0 -${M_PI/2}" rpy="0 ${M_PI/2} 0" /> -->
<geometry>
<cylinder radius="0.11" length="0.11" />
</geometry>
</collision>
</link>

<transmission name="${name}_trans" type="SimpleTransmission">
<type>transmission_interface/SimpleTransmission</type>
<actuator name="${name}_motor">
<mechanicalReduction>1</mechanicalReduction>
</actuator>
<joint name="${name}_joint">
<hardwareInterface>hardware_interface/VelocityJointInterface</hardwareInterface>
</joint>
</transmission>

</xacro:macro>

</robot>
